Workbook
Name BIGADD: _xlfn.LAMBDA(_xlpm.a,_xlpm.b,BIGTEXT(BIGNORM(BIGLIMBS(_xlpm.a)+BIGLIMBS(_xlpm.b))))
Name BIGLIMBS: _xlfn.LAMBDA(_xlpm.s,VALUE(MID(REPT("0",42-LEN(_xlpm.s))&_xlpm.s,_xlfn.SEQUENCE(7,,1,6),6)))
Name BIGNORM: _xlfn.LAMBDA(_xlpm.v,_xlfn.REDUCE(_xlpm.v,_xlfn.SEQUENCE(7),_xlfn.LAMBDA(_xlpm.a,_xlpm.k,_xlfn.LET(_xlpm.c,INT(_xlpm.a/1000000),_xlpm.a-_xlpm.c*1000000+_xlfn.VSTACK(_xlfn.DROP(_xlpm.c,1),0)))))
Name BIGTEXT: _xlfn.LAMBDA(_xlpm.v,_xlfn.LET(_xlpm.t,_xlfn.TEXTJOIN("",,TEXT(_xlpm.v,"000000")),MID(_xlpm.t,IFERROR(MATCH(TRUE,INDEX(MID(_xlpm.t,_xlfn.SEQUENCE(42),1)<>"0",0),0),42),50)))
Name SECP256K1_ORDER: 1.15792089237316E+77

Sheet puzzle-all
A1: bits | B1: range_min | C1: range_max | D1: address | E1: btc_value (BTC) | F1: hash160_compressed | G1: public_key | H1: private_key
A2: 1 | B2: 1 | C2: 1 | D2: 1BgGZ9tcN4rm9KBzDn7KprQz87SZ26SAMH | E2: 0.001 | F2: 751e76e8199196d454941c45d1b3a323f1433bd6 | G2: 0279be667ef9dcbbac55a06295ce870b07029bfcdb2dce28d959f2815b16f81798 | H2: 0000000000000000000000000000000000000000000000000000000000000001
A3: 2 | B3: 2 | C3: 3 | D3: 1CUNEBjYrCn2y1SdiUMohaKUi4wpP326Lb | E3: 0.002 | F3: 7dd65592d0ab2fe0d0257d571abf032cd9db93dc | G3: 02f9308a019258c31049344f85f89d5229b531c845836f99b08601f113bce036f9 | H3: 0000000000000000000000000000000000000000000000000000000000000003
A4: 3 | B4: 4 | C4: 7 | D4: 19ZewH8Kk1PDbSNdJ97FP4EiCjTRaZMZQA | E4: 0.003 | F4: 5dedfbf9ea599dd4e3ca6a80b333c472fd0b3f69 | G4: 025cbdf0646e5db4eaa398f365f2ea7a0e3d419b7e0330e39ce92bddedcac4f9bc | H4: 0000000000000000000000000000000000000000000000000000000000000007
A5: 4 | B5: 8 | C5: f | D5: 1EhqbyUMvvs7BfL8goY6qcPbD6YKfPqb7e | E5: 0.004 | F5: 9652d86bedf43ad264362e6e6eba6eb764508127 | G5: 022f01e5e15cca351daff3843fb70f3c2f0a1bdd05e5af888a67784ef3e10a2a01 | H5: 0000000000000000000000000000000000000000000000000000000000000008
A6: 5 | B6: 10 | C6: 1f | D6: 1E6NuFjCi27W5zoXg8TRdcSRq84zJeBW3k | E6: 0.005 | F6: 8f9dff39a81ee4abcbad2ad8bafff090415a2be8 | G6: 02352bbf4a4cdd12564f93fa332ce333301d9ad40271f8107181340aef25be59d5 | H6: 0000000000000000000000000000000000000000000000000000000000000015
A7: 6 | B7: 20 | C7: 3f | D7: 1PitScNLyp2HCygzadCh7FveTnfmpPbfp8 | E7: 0.006 | F7: f93ec34e9e34a8f8ff7d600cdad83047b1bcb45c | G7: 03f2dac991cc4ce4b9ea44887e5c7c0bce58c80074ab9d4dbaeb28531b7739f530 | H7: 0000000000000000000000000000000000000000000000000000000000000031
A8: 7 | B8: 40 | C8: 7f | D8: 1McVt1vMtCC7yn5b9wgX1833yCcLXzueeC | E8: 0.007 | F8: e2192e8a7dd8dd1c88321959b477968b941aa973 | G8: 0296516a8f65774275278d0d7420a88df0ac44bd64c7bae07c3fe397c5b3300b23 | H8: 000000000000000000000000000000000000000000000000000000000000004c
A9: 8 | B9: 80 | C9: ff | D9: 1M92tSqNmQLYw33fuBvjmeadirh1ysMBxK | E9: 0.008 | F9: dce76b2613052ea012204404a97b3c25eac31715 | G9: 0308bc89c2f919ed158885c35600844d49890905c79b357322609c45706ce6b514 | H9: 00000000000000000000000000000000000000000000000000000000000000e0
A10: 9 | B10: 100 | C10: 1ff | D10: 1CQFwcjw1dwhtkVWBttNLDtqL7ivBonGPV | E10: 0.009 | F10: 7d0f6c64afb419bbd7e971e943d7404b0e0daab4 | G10: 0243601d61c836387485e9514ab5c8924dd2cfd466af34ac95002727e1659d60f7 | H10: 00000000000000000000000000000000000000000000000000000000000001d3
A11: 10 | B11: 200 | C11: 3ff | D11: 1LeBZP5QCwwgXRtmVUvTVrraqPUokyLHqe | E11: 0.01 | F11: d7729816650e581d7462d52ad6f732da0e2ec93b | G11: 03a7a4c30291ac1db24b4ab00c442aa832f7794b5a0959bec6e8d7fee802289dcd | H11: 0000000000000000000000000000000000000000000000000000000000000202
A12: 11 | B12: 400 | C12: 7ff | D12: 1PgQVLmst3Z314JrQn5TNiys8Hc38TcXJu | E12: 0.011 | F12: f8c698da3164ef8fa4258692d118cc9a902c5acc | G12: 038b05b0603abd75b0c57489e451f811e1afe54a8715045cdf4888333f3ebc6e8b | H12: 0000000000000000000000000000000000000000000000000000000000000483
A13: 12 | B13: 800 | C13: fff | D13: 1DBaumZxUkM4qMQRt2LVWyFJq5kDtSZQot | E13: 0.012 | F13: 85a1f9ba4da24c24e582d9b891dacbd1b043f971 | G13: 038b00fcbfc1a203f44bf123fc7f4c91c10a85c8eae9187f9d22242b4600ce781c | H13: 0000000000000000000000000000000000000000000000000000000000000a7b
... A71: 70 | B71: 200000000000000000 | C71: 3fffffffffffffffff | D71: 19YZECXj3SxEZMoUeJ1yiPsw8xANe7M7QR | E71: 0.7 | F71: 5db8cda53a6a002db10365967d7f85d19e171b10 | G71: 0290e6900a58d33393bc1097b5aed31f2e4e7cbd3e5466af958665bc0121248483 | H71: 0000000000000000000000000000000000000000000000349b84b6431a6c4ef1
A72: 71 | B72: 400000000000000000 | C72: 7fffffffffffffffff | D72: 1PWo3JeB9jrGwfHDNpdGK54CRas7fsVzXU | E72: 7.1 | F72: f6f5431d25bbf7b12e8add9af5e3475c44a0a5b8
A73: 72 | B73: 800000000000000000 | C73: ffffffffffffffffff | D73: 1JTK7s9YVYywfm5XUH7RNhHJH1LshCaRFR | E73: 7.2 | F73: bf7413e8df4e7a34ce9dc13e2f2648783ec54adb
A74: 73 | B74: 1000000000000000000 | C74: 1ffffffffffffffffff | D74: 12VVRNPi4SJqUTsp6FmqDqY5sGosDtysn4 | E74: 7.3 | F74: 105b7f253f0ebd7843adaebbd805c944bfb863e4
A75: 74 | B75: 2000000000000000000 | C75: 3ffffffffffffffffff | D75: 1FWGcVDK3JGzCC3WtkYetULPszMaK2Jksv | E75: 7.4 | F75: 9f1adb20baeacc38b3f49f3df6906a0e48f2df3d
A76: 75 | B76: 4000000000000000000 | C76: 7ffffffffffffffffff | D76: 1J36UjUByGroXcCvmj13U6uwaVv9caEeAt | E76: 0.75 | F76: badf8b0d34289e679ec65c6c61d3a974353be5cf | G76: 03726b574f193e374686d8e12bc6e4142adeb06770e0a2856f5e4ad89f66044755 | H76: 0000000000000000000000000000000000000000000004c5ce114686a1336e07
A77: 76 | B77: 8000000000000000000 | C77: fffffffffffffffffff | D77: 1DJh2eHFYQfACPmrvpyWc8MSTYKh7w9eRF | E77: 7.6 | F77: 86f9fea5cdecf033161dd2f8f8560768ae0a6d14
A78: 77 | B78: 10000000000000000000 | C78: 1fffffffffffffffffff | D78: 1Bxk4CQdqL9p22JEtDfdXMsng1XacifUtE | E78: 7.7 | F78: 783c138ac81f6a52398564bb17455576e8525b29
A79: 78 | B79: 20000000000000000000 | C79: 3fffffffffffffffffff | D79: 15qF6X51huDjqTmF9BJgxXdt1xcj46Jmhb | E79: 7.8 | F79: 35003c3ef8759c92092f8488fca59a042859018c
A80: 79 | B80: 40000000000000000000 | C80: 7fffffffffffffffffff | D80: 1ARk8HWJMn8js8tQmGUJeQHjSE7KRkn2t8 | E80: 7.9 | F80: 67671d5490c272e3ab7ddd34030d587738df33da
A81: 80 | B81: 80000000000000000000 | C81: ffffffffffffffffffff | D81: 1BCf6rHUW6m3iH2ptsvnjgLruAiPQQepLe | E81: 0.8 | F81: 6fe5a36eef0684af0b91f3b6cfc972d68c4f6fab | G81: 037e1238f7b1ce757df94faa9a2eb261bf0aeb9f84dbf81212104e78931c2a19dc | H81: 00000000000000000000000000000000000000000000ea1a5c66dcc11b5ad180
A82: 81 | B82: 100000000000000000000 | C82: 1ffffffffffffffffffff | D82: 15qsCm78whspNQFydGJQk5rexzxTQopnHZ | E82: 8.1 | F82: 351e605fac813965951ba433b7c2956bf8ad95ce
A83: 82 | B83: 200000000000000000000 | C83: 3ffffffffffffffffffff | D83: 13zYrYhhJxp6Ui1VV7pqa5WDhNWM45ARAC | E83: 8.2 | F83: 20d28d4e87543947c7e4913bcdceaa16e2f8f061
A84: 83 | B84: 400000000000000000000 | C84: 7ffffffffffffffffffff | D84: 14MdEb4eFcT3MVG5sPFG4jGLuHJSnt1Dk2 | E84: 8.3 | F84: 24cef184714bbd030833904f5265c9c3e12a95a2
A85: 84 | B85: 800000000000000000000 | C85: fffffffffffffffffffff | D85: 1CMq3SvFcVEcpLMuuH8PUcNiqsK1oicG2D | E85: 8.4 | F85: 7c99ce73e19f9fbfcce4825ae88261e2b0b0b040
A86: 85 | B86: 1000000000000000000000 | C86: 1fffffffffffffffffffff | D86: 1Kh22PvXERd2xpTQk3ur6pPEqFeckCJfAr | E86: 0.85 | F86: cd03c1e6268ce9b89e3c3eeab8d0f1b6e8cac281 | G86: 0329c4574a4fd8c810b7e42a4b398882b381bcd85e40c6883712912d167c83e73a | H86: 00000000000000000000000000000000000000000011720c4f018d51b8cebba8
A87: 86 | B87: 2000000000000000000000 | C87: 3fffffffffffffffffffff | D87: 1K3x5L6G57Y494fDqBfrojD28UJv4s5JcK | E87: 8.6 | F87: c60111ed3d63b49665747b0e31eb382da5193535
A88: 87 | B88: 4000000000000000000000 | C88: 7fffffffffffffffffffff | D88: 1PxH3K1Shdjb7gSEoTX7UPDZ6SH4qGPrvq | E88: 8.7 | F88: fbc708d671c03e26661b9c08f77598a529858b5e
A89: 88 | B89: 8000000000000000000000 | C89: ffffffffffffffffffffff | D89: 16AbnZjZZipwHMkYKBSfswGWKDmXHjEpSf | E89: 8.8 | F89: 38a968fdfb457654c51bcfc4f9174d6ee487bb41
A90: 89 | B90: 10000000000000000000000 | C90: 1ffffffffffffffffffffff | D90: 19QciEHbGVNY4hrhfKXmcBBCrJSBZ6TaVt | E90: 8.9 | F90: 5c3862203d1e44ab3af441503e22db97b1c5097e
A91: 90 | B91: 20000000000000000000000 | C91: 3ffffffffffffffffffffff | D91: 1L12FHH2FHjvTviyanuiFVfmzCy46RRATU | E91: 0.9 | F91: d06b6e206691295ec345782d7ea0686969d8674b | G91: 035c38bd9ae4b10e8a250857006f3cfd98ab15a6196d9f4dfd25bc7ecc77d788d5 | H91: 000000000000000000000000000000000000000002ce00bb2136a445c71e85bf
A92: 91 | B92: 40000000000000000000000 | C92: 7ffffffffffffffffffffff | D92: 1EzVHtmbN4fs4MiNk3ppEnKKhsmXYJ4s74 | E92: 9.1 | F92: 9978f61b92d16c5f1a463a0995df70da1f7a7d2a
A93: 92 | B93: 80000000000000000000000 | C93: fffffffffffffffffffffff | D93: 1AE8NzzgKE7Yhz7BWtAcAAxiFMbPo82NB5 | E93: 9.2 | F93: 6534b31208fe6e100d29f9c9c75aac8bf06fbb38
A94: 93 | B94: 100000000000000000000000 | C94: 1fffffffffffffffffffffff | D94: 17Q7tuG2JwFFU9rXVj3uZqRtioH3mx2Jad | E94: 9.3 | F94: 463013cd41279f2fd0c31d0a16db3972bfffac8d
A95: 94 | B95: 200000000000000000000000 | C95: 3fffffffffffffffffffffff | D95: 1K6xGMUbs6ZTXBnhw1pippqwK6wjBWtNpL | E95: 9.4 | F95: c6927a00970d0165327d0a6db7950f05720c295c
A96: 95 | B96: 400000000000000000000000 | C96: 7fffffffffffffffffffffff | D96: 19eVSDuizydXxhohGh8Ki9WY9KsHdSwoQC | E96: 0.95 | F96: 5ed822125365274262191d2b77e88d436dd56d88 | G96: 02967a5905d6f3b420959a02789f96ab4c3223a2c4d2762f817b7895c5bc88a045 | H96: 0000000000000000000000000000000000000000527a792b183c7f64a0e8b1f4
A97: 96 | B97: 800000000000000000000000 | C97: ffffffffffffffffffffffff | D97: 15ANYzzCp5BFHcCnVFzXqyibpzgPLWaD8b | E97: 9.6 | F97: 2da63cbd251d23c7b633cb287c09e6cf888b3fe4
...

Sheet Key Analysis
A1: bits | B1: key_hex | C1: key_binary | D1: key_decimal | E1: offset_from_range_min | F1: relative_position | G1: popcount | H1: trailing_zeros | I1: xor_prev_binary | J1: hamming_prev | K1: key_base4 | L1: key_octal | M1: key_base32 | N1: bit_reversed_binary | O1: bit_reversed_decimal | P1: gray_code_binary | Q1: complement_in_range_binary | R1: dist_to_range_max | S1: byte_reversed_hex_32B | T1: ratio_to_prev | U1: ones_fraction | V1: wif_compressed (static) | W1: wif_uncompressed (static) | X1: key_base64_32B (static) | Y1: hash160_binary | Z1: hamming_vs_hash160_low_n | AA1: hamming_vs_hash160_high_n | AB1: hamming_vs_hash160_full160 | AC1: z_low_n | AD1: z_high_n | AE1: digit_count | AF1: digit_sum | AG1: digital_root | AH1: decimal_reversed | AI1: log2_key | AJ1: log2_offset | AK1: rotl1_binary | AL1: rotr1_binary | AM1: bitwise_not_n_bits | AN1: longest_run_0 | AO1: longest_run_1 | AP1: run_count | AQ1: run_length_string | AR1: distinct_hex_digits | AS1: most_common_hex_digit | AT1: hex_digit_counts | AU1: mod_3 | AV1: mod_5 | AW1: mod_7 | AX1: mod_11 | AY1: mod_256 | AZ1: mod_65536 | BA1: key_minus_prev | BB1: key_minus_2x_prev | BC1: key_plus_1 | BD1: key_minus_1 | BE1: hex_0x_spaced_bytes | BF1: byte_values_decimal | BG1: ascii_reading | BH1: ipv4_low32 | BI1: unix_time_utc_if_lt_2^32 | BJ1: key_base36 (static) | BK1: key_base32_rfc4648 (static) | BL1: key_base64url (static) | BM1: n_minus_k_hex (static) | BN1: pubkey_x_hex (static) | BO1: pubkey_y_hex (static) | BP1: pubkey_uncompressed_hex (static) | BQ1: hash160_uncompressed (static) | BR1: address_p2pkh_uncompressed (static) | BS1: address_p2sh_p2wpkh (static) | BT1: address_bech32_p2wpkh (static) | BU1: key_over_curve_order | BV1: pubkey_x_binary | BW1: hamming_x_vs_key_low_n | BX1: hamming_x_vs_key_high_n | BY1: z_x_low_n | BZ1: z_x_high_n | CA1: runs_test_z | CB1: serial_corr_bits | CC1: longest_run_expected | CD1: longest_run_excess | CE1: hex_chi_square | CF1: hex_chi_p | CG1: common_prefix_prev | CH1: common_suffix_prev | CI1: relpos_drift_prev | CJ1: prev_key_in_key_hex | CK1: prev_key_in_key_bin | CL1: prev_key_bin_offset | CM1: key_mod_prev | CN1: relpos_minus_half | CO1: hex_nibble_reversed | CP1: hex_nibble_reversed_decimal | CQ1: bcd_reading | CR1: decimal_as_hex_value | CS1: hex_grouped_4 | CT1: hex_grouped_8_upper | CU1: key_in_words_if_small | CV1: is_prime (static) | CW1: smallest_prime_factor (static) | CX1: distinct_prime_factors (static) | CY1: factorization (static) | CZ1: is_perfect_square (static) | DA1: is_perfect_cube (static) | DB1: nearest_pow2_exp (static) | DC1: dist_to_nearest_pow2 (static) | DD1: nearest_fibonacci (static) | DE1: dist_to_fibonacci (static) | DF1: nearest_triangular (static) | DG1: dist_to_triangular (static) | DH1: parity (static) | DI1: wif_testnet_compressed (static) | DJ1: address_testnet_p2pkh (static) | DK1: address_testnet_bech32 (static) | DL1: address_taproot_p2tr (static) | DM1: taproot_output_key_x (static) | DN1: wif_litecoin_compressed (static) | DO1: address_litecoin_p2pkh (static) | DP1: address_litecoin_bech32 (static) | DQ1: wif_dogecoin_compressed (static) | DR1: address_dogecoin_p2pkh (static) | DS1: pubkey_compressed_base64 (static) | DT1: hash160_uncompressed_binary
A2: 1 | B2: 1 | C2: 1 | D2: 1 | E2: 0 | F2: 0 | G2: 1 | H2: 0 | J2: 0 | K2: 1 | L2: 1 | M2: 1 | N2: 1 | O2: 1 | P2: 1 | Q2: 1 | R2: 0 | S2: 0100000000000000000000000000000000000000000000000000000000000000 | U2: 1 | V2: KwDiBf89QgGbjEhKnhXJuH7LrciVrZi3qYjgd9M7rFU73sVHnoWn | W2: 5HpHagT65TZzG1PH3CSu63k8DbpvD8s5ip4nEB3kEsreAnchuDf | X2: AAAAAAAAAAAAAAAAAAAAAAAAAAAAAAAAAAAAAAAAAAE= | Y2: 0111010100011110011101101110100000011001100100011001011011010100010101001001010000011100010001011101000110110011101000110010001111110001010000110011101111010110 | Z2: 1 | AA2: 1 | AB2: 79 | AC2: 1 | AD2: 1 | AE2: 1 | AF2: 1 | AG2: 1 | AH2: 1 | AI2: 0 | AK2: 1 | AL2: 1 | AM2: 0 | AN2: 0 | AO2: 1 | AP2: 1 | AQ2: 1x1 | AR2: 1 | AS2: 1 | AT2: 1:1 | AU2: 1 | AV2: 1 | AW2: 1 | AX2: 1 | AY2: 1 | AZ2: 1 | BC2: 2 | BD2: 0 | BE2: 0x00 00 00 00 00 00 00 00 00 00 00 00 00 00 00 00 00 00 00 00 00 00 00 00 00 00 00 00 00 00 00 01 | BF2: 0,0,0,0,0,0,0,0,0,0,0,0,0,0,0,0,0,0,0,0,0,0,0,0,0,0,0,0,0,0,0,1 | BG2: ................................ | BH2: 0.0.0.1 | BI2: 25569 | BJ2: 1 | BK2: AAAAAAAAAAAAAAAAAAAAAAAAAAAAAAAAAAAAAAAAAAAAAAAAAAAQ==== | BL2: AAAAAAAAAAAAAAAAAAAAAAAAAAAAAAAAAAAAAAAAAAE | BM2: fffffffffffffffffffffffffffffffebaaedce6af48a03bbfd25e8cd0364140 | BN2: 79be667ef9dcbbac55a06295ce870b07029bfcdb2dce28d959f2815b16f81798 | BO2: 483ada7726a3c4655da4fbfc0e1108a8fd17b448a68554199c47d08ffb10d4b8 | BP2: 0479be667ef9dcbbac55a06295ce870b07029bfcdb2dce28d959f2815b16f81798483ada7726a3c4655da4fbfc0e1108a8fd17b448a68554199c47d08ffb10d4b8 | BQ2: 91b24bf9f5288532960ac687abb035127b1d28a5 | BR2: 1EHNa6Q4Jz2uvNExL497mE43ikXhwF6kZm | BS2: 3JvL6Ymt8MVWiCNHC7oWU6nLeHNJKLZGLN | BT2: bc1qw508d6qejxtdg4y5r3zarvary0c5xw7kv8f3t4 | BU2: 8.6361686e-78 | BV2: 0111100110111110011001100111111011111001110111001011101110101100010101011010000001100010100101011100111010000111000010110000011100000010100110111111110011011011001011011100111000101000110110010101100111110010100000010101101100010110111110000001011110011000 | BW2: 1 | BX2: 1 | BY2: 1 | BZ2: 1 | CA2: =IF(B2="","",IF(A2<8,"",_xlfn.LET(_xlpm.n,A2,_xlpm.k,G2,_xlpm.R,AP2,_xlpm.mu,1+2*_xlpm.k*(_xlpm.n-_xlpm.k)/_xlpm.n,_xlpm.v,2*_xlpm.k*(_xlpm.n-_xlpm.k)*(2*_xlpm.k*(_xlpm.n-_xlpm.k)-_xlpm.n)/(_xlpm.n^2*(_xlpm.n-1)),IF(_xlpm.v<=0,"",(_xlpm.R-_xlpm.mu)/SQRT(_xlpm.v))))) | CB2: {=IF(B2="","",IF(A2<8,"",_xlfn.LET(_xlpm.b,--MID(C2,_xlfn.SEQUENCE(A2-1),1),_xlpm.c,--MID(C2,_xlfn.SEQUENCE(A2-1,,2),1),IFERROR(CORREL(_xlpm.b,_xlpm.c),""))))} | CC2: =IF(B2="","",LOG(A2,2)) -> 0 | CD2: =IF(B2="","",MAX(AN2,AO2)-CC2) -> 1 | CE2: {=IF(B2="","",IF(LEN(B2)<16,"",_xlfn.LET(_xlpm.d,MID("0123456789abcdef",_xlfn.SEQUENCE(16),1),_xlpm.c,LEN(B2)-LEN(SUBSTITUTE(B2,_xlpm.d,"")),_xlpm.ex,LEN(B2)/16,SUM((_xlpm.c-_xlpm.ex)^2/_xlpm.ex))))} | CF2: =IF(CE2="","",_xlfn.CHISQ.DIST.RT(CE2,15)) | CG2: ="" | CH2: ="" | CI2: ="" | CJ2: ="" | CK2: ="" | CL2: ="" | CM2: ="" | CN2: =IF(B2="","",F2-0.5) -> -0.5 | CO2: {=IF(B2="","",_xlfn.TEXTJOIN("",,MID(B2,_xlfn.SEQUENCE(LEN(B2),,LEN(B2),-1),1)))} -> 1 | CP2: {=IF(B2="","",BASE2DEC(CO2,16))} -> 1 | CQ2: =IF(B2="","",IF(AND(LEN(B2)<16,LEN(B2)=LEN(SUBSTITUTE(SUBSTITUTE(SUBSTITUTE(SUBSTITUTE(SUBSTITUTE(SUBSTITUTE(B2,"a",""),"b",""),"c",""),"d",""),"e",""),"f",""))),--B2,"")) -> 1 | CR2: {=IF(B2="","",IF(LEN(D2)<=15,BASE2DEC(D2,16),""))} -> 1 | CS2: {=IF(B2="","",_xlfn.LET(_xlpm.p,REPT("0",MOD(-LEN(B2),4))&B2,_xlfn.TEXTJOIN(" ",,MID(_xlpm.p,_xlfn.SEQUENCE(LEN(_xlpm.p)/4,,1,4),4))))} -> 0001 | CT2: {=IF(B2="","",UPPER(_xlfn.LET(_xlpm.p,REPT("0",64-LEN(B2))&B2,_xlfn.TEXTJOIN(" ",,MID(_xlpm.p,_xlfn.SEQUENCE(8,,1,8),8)))))} -> 00000000 00000000 00000000 00000000 00000000 00000000 00000000 00000001 | CU2: {=IF(B2="","",IF(LEN(D2)<=6,_xlfn.LET(_xlpm.n,VALUE(D2),_xlpm.ones,{"","one","two","three","four","five","six","seven","eight","nine","ten","eleven","twelve","thirteen","fourteen","fifteen","sixteen","seventeen","eighteen","nineteen"},_xlpm.tens,{"","","twenty","thirty","forty","fifty","sixty","seventy","eighty","ninety"},_xlpm.f,_xlfn.LAMBDA(_xlpm.x,TRIM(IF(_xlpm.x>=100,INDEX(_xlpm.ones,INT(_xlpm.x/100)+1)&" hundred ","")&IF(MOD(_xlpm.x,100)<20,INDEX(_xlpm.ones,MOD(_xlpm.x,100)+1),INDEX(_xlpm.tens,INT(MOD(_xlpm.x,100)/10)+1)&IF(MOD(_xlpm.x,10)>0,"-"&INDEX(_xlpm.ones,MOD(_xlpm.x,10)+1),"")))),TRIM(IF(_xlpm.n>=1000,_xlpm.f(INT(_xlpm.n/1000))&" thousand ","")&IF(MOD(_xlpm.n,1000)>0,_xlpm.f(MOD(_xlpm.n,1000)),""))),""))} -> one | CV2: no | CW2: >2e6 (not found) | CZ2: yes | DA2: yes | DB2: 0 | DC2: 0 below 2^0 | DD2: 1 | DE2: 0 | DF2: 1 | DG2: 0 | DH2: odd | DI2: cMahea7zqjxrtgAbB7LSGbcQUr1uX1ojuat9jZodMN87JcbXMTcA | DJ2: mrCDrCybB6J1vRfbwM5hemdJz73FwDBC8r | DK2: tb1qw508d6qejxtdg4y5r3zarvary0c5xw7kxpjzsx | DL2: bc1pmfr3p9j00pfxjh0zmgp99y8zftmd3s5pmedqhyptwy6lm87hf5sspknck9 | DM2: da4710964f7852695de2da025290e24af6d8c281de5a0b902b7135fd9fd74d21 | DN2: T33ydQRKp4FCW5LCLLUB7deioUMoveiwekdwUwyfRDeGZm76aUjV | DO2: LVuDpNCSSj6pQ7t9Pv6d6sUkLKoqDEVUnJ | DP2: ltc1qw508d6qejxtdg4y5r3zarvary0c5xw7kgmn4n9 | DQ2: QNcdLVw8fHkixm6NNyN6nVwxKek4u7qrioRbQmjxac5TVoTtZuot | DR2: DFpN6QqFfUm3gKNaxN6tNcab1FArL9cZLE | DS2: Anm+Zn753LusVaBilc6HCwcCm/zbLc4o2VnygVsW+BeY | DT2: {=IF(B2="","",_xlfn.TEXTJOIN("",,HEX2BIN(MID(BQ2,_xlfn.SEQUENCE(40),1),4)))} -> 1001000110110010010010111111100111110101001010001000010100110010100101100000101011000110100001111010101110110000001101010001001001111011000111010010100010100101
A3: 2 | B3: 3 | C3: 11 | D3: 3 | E3: 1 | F3: 0.5 | G3: 2 | H3: 0 | I3: 10 | J3: 1 | K3: 3 | L3: 3 | M3: 3 | N3: 11 | O3: 3 | P3: 10 | Q3: 10 | R3: 0 | S3: 0300000000000000000000000000000000000000000000000000000000000000 | T3: 3 | U3: 1 | V3: KwDiBf89QgGbjEhKnhXJuH7LrciVrZi3qYjgd9M7rFU74sHUHy8S | W3: 5HpHagT65TZzG1PH3CSu63k8DbpvD8s5ip4nEB3kEsreB1FQ8BZ | X3: AAAAAAAAAAAAAAAAAAAAAAAAAAAAAAAAAAAAAAAAAAM= | Y3: 0111110111010110010101011001001011010000101010110010111111100000110100000010010101111101010101110001101010111111000000110010110011011001110110111001001111011100 | Z3: 2 | AA3: 1 | AB3: 88 | AC3: 1.4142136 | AD3: 0 | AE3: 1 | AF3: 3 | AG3: 3 | AH3: 3 | AI3: 1.5849625 | AJ3: 0 | AK3: 11 | AL3: 11 | AM3: 00 | AN3: 0 | AO3: 2 | AP3: 1 | AQ3: 1x2 | AR3: 1 | AS3: 3 | AT3: 3:1 | AU3: 0 | AV3: 3 | AW3: 3 | AX3: 3 | AY3: 3 | AZ3: 3 | BA3: 2 | BB3: 1 | BC3: 4 | BD3: 2 | BE3: 0x00 00 00 00 00 00 00 00 00 00 00 00 00 00 00 00 00 00 00 00 00 00 00 00 00 00 00 00 00 00 00 03 | BF3: 0,0,0,0,0,0,0,0,0,0,0,0,0,0,0,0,0,0,0,0,0,0,0,0,0,0,0,0,0,0,0,3 | BG3: ................................ | BH3: 0.0.0.3 | BI3: 25569 | BJ3: 3 | BK3: AAAAAAAAAAAAAAAAAAAAAAAAAAAAAAAAAAAAAAAAAAAAAAAAAABQ==== | BL3: AAAAAAAAAAAAAAAAAAAAAAAAAAAAAAAAAAAAAAAAAAM | BM3: fffffffffffffffffffffffffffffffebaaedce6af48a03bbfd25e8cd036413e | BN3: f9308a019258c31049344f85f89d5229b531c845836f99b08601f113bce036f9 | BO3: 388f7b0f632de8140fe337e62a37f3566500a99934c2231b6cb9fd7584b8e672 | BP3: 04f9308a019258c31049344f85f89d5229b531c845836f99b08601f113bce036f9388f7b0f632de8140fe337e62a37f3566500a99934c2231b6cb9fd7584b8e672 | BQ3: ec7eced2c57ed1292bc4eb9bfd13c9f7603bc338 | BR3: 1NZUP3JAc9JkmbvmoTv7nVgZGtyJjirKV1 | BS3: 3BM3eLQZbwubG3XwwxJmd9qxwMJn7yUTSn | BT3: bc1q0ht9tyks4vh7p5p904t340cr9nvahy7u3re7zg | BU3: 2.5908506e-77 | BV3: 1111100100110000100010100000000110010010010110001100001100010000010010010011010001001111100001011111100010011101010100100010100110110101001100011100100001000101100000110110111110011001101100001000011000000001111100010001001110111100111000000011011011111001 | BW3: 1 | BX3: 0 | BY3: 0 | BZ3: -1.4142136 | CA3: =IF(B3="","",IF(A3<8,"",_xlfn.LET(_xlpm.n,A3,_xlpm.k,G3,_xlpm.R,AP3,_xlpm.mu,1+2*_xlpm.k*(_xlpm.n-_xlpm.k)/_xlpm.n,_xlpm.v,2*_xlpm.k*(_xlpm.n-_xlpm.k)*(2*_xlpm.k*(_xlpm.n-_xlpm.k)-_xlpm.n)/(_xlpm.n^2*(_xlpm.n-1)),IF(_xlpm.v<=0,"",(_xlpm.R-_xlpm.mu)/SQRT(_xlpm.v))))) | CB3: {=IF(B3="","",IF(A3<8,"",_xlfn.LET(_xlpm.b,--MID(C3,_xlfn.SEQUENCE(A3-1),1),_xlpm.c,--MID(C3,_xlfn.SEQUENCE(A3-1,,2),1),IFERROR(CORREL(_xlpm.b,_xlpm.c),""))))} | CC3: =IF(B3="","",LOG(A3,2)) -> 1 | CD3: =IF(B3="","",MAX(AN3,AO3)-CC3) -> 1 | CE3: {=IF(B3="","",IF(LEN(B3)<16,"",_xlfn.LET(_xlpm.d,MID("0123456789abcdef",_xlfn.SEQUENCE(16),1),_xlpm.c,LEN(B3)-LEN(SUBSTITUTE(B3,_xlpm.d,"")),_xlpm.ex,LEN(B3)/16,SUM((_xlpm.c-_xlpm.ex)^2/_xlpm.ex))))} | CF3: =IF(CE3="","",_xlfn.CHISQ.DIST.RT(CE3,15)) | CG3: {=IF(OR(B3="",B2=""),"",_xlfn.LET(_xlpm.a,C3,_xlpm.b,REPT("0",A3-LEN(C2))&C2,_xlpm.m,MID(_xlpm.a,_xlfn.SEQUENCE(A3),1)=MID(_xlpm.b,_xlfn.SEQUENCE(A3),1),IFERROR(MATCH(FALSE,_xlpm.m,0)-1,A3)))} -> 0 | CH3: {=IF(OR(B3="",B2=""),"",_xlfn.LET(_xlpm.a,C3,_xlpm.b,REPT("0",A3-LEN(C2))&C2,_xlpm.n,A3,_xlpm.m,MID(_xlpm.a,_xlfn.SEQUENCE(_xlpm.n,,_xlpm.n,-1),1)=MID(_xlpm.b,_xlfn.SEQUENCE(_xlpm.n,,_xlpm.n,-1),1),IFERROR(MATCH(FALSE,_xlpm.m,0)-1,_xlpm.n)))} -> 1 | CI3: =IF(OR(B3="",B2=""),"",F3-F2) -> 0.5 | CJ3: =IF(OR(B3="",B2=""),"",IFERROR(FIND(B2,B3)>0,FALSE)) -> FALSE | CK3: =IF(OR(B3="",B2=""),"",IFERROR(FIND(C2,C3)>0,FALSE)) -> TRUE | CL3: =IF(OR(B3="",B2=""),"",IFERROR(FIND(C2,C3),"")) -> 1 | CM3: {=IF(OR(B3="",B2=""),"",_xlfn.LET(_xlpm.pv,D2,_xlpm.ra,BIGSUB(D3,_xlpm.pv),_xlpm.rb,BIGSUB(_xlpm.ra,_xlpm.pv),_xlpm.rc,BIGSUB(_xlpm.rb,_xlpm.pv),IF(LEFT(_xlpm.rb,1)="-",_xlpm.ra,IF(LEFT(_xlpm.rc,1)="-",_xlpm.rb,_xlpm.rc))))} -> 0 | CN3: =IF(B3="","",F3-0.5) -> 0 | CO3: {=IF(B3="","",_xlfn.TEXTJOIN("",,MID(B3,_xlfn.SEQUENCE(LEN(B3),,LEN(B3),-1),1)))} -> 3 | CP3: {=IF(B3="","",BASE2DEC(CO3,16))} -> 3 | CQ3: =IF(B3="","",IF(AND(LEN(B3)<16,LEN(B3)=LEN(SUBSTITUTE(SUBSTITUTE(SUBSTITUTE(SUBSTITUTE(SUBSTITUTE(SUBSTITUTE(B3,"a",""),"b",""),"c",""),"d",""),"e",""),"f",""))),--B3,"")) -> 3 | CR3: {=IF(B3="","",IF(LEN(D3)<=15,BASE2DEC(D3,16),""))} -> 3 | CS3: {=IF(B3="","",_xlfn.LET(_xlpm.p,REPT("0",MOD(-LEN(B3),4))&B3,_xlfn.TEXTJOIN(" ",,MID(_xlpm.p,_xlfn.SEQUENCE(LEN(_xlpm.p)/4,,1,4),4))))} -> 0003 | CT3: {=IF(B3="","",UPPER(_xlfn.LET(_xlpm.p,REPT("0",64-LEN(B3))&B3,_xlfn.TEXTJOIN(" ",,MID(_xlpm.p,_xlfn.SEQUENCE(8,,1,8),8)))))} -> 00000000 00000000 00000000 00000000 00000000 00000000 00000000 00000003 | CU3: {=IF(B3="","",IF(LEN(D3)<=6,_xlfn.LET(_xlpm.n,VALUE(D3),_xlpm.ones,{"","one","two","three","four","five","six","seven","eight","nine","ten","eleven","twelve","thirteen","fourteen","fifteen","sixteen","seventeen","eighteen","nineteen"},_xlpm.tens,{"","","twenty","thirty","forty","fifty","sixty","seventy","eighty","ninety"},_xlpm.f,_xlfn.LAMBDA(_xlpm.x,TRIM(IF(_xlpm.x>=100,INDEX(_xlpm.ones,INT(_xlpm.x/100)+1)&" hundred ","")&IF(MOD(_xlpm.x,100)<20,INDEX(_xlpm.ones,MOD(_xlpm.x,100)+1),INDEX(_xlpm.tens,INT(MOD(_xlpm.x,100)/10)+1)&IF(MOD(_xlpm.x,10)>0,"-"&INDEX(_xlpm.ones,MOD(_xlpm.x,10)+1),"")))),TRIM(IF(_xlpm.n>=1000,_xlpm.f(INT(_xlpm.n/1000))&" thousand ","")&IF(MOD(_xlpm.n,1000)>0,_xlpm.f(MOD(_xlpm.n,1000)),""))),""))} -> three | CV3: yes | CW3: 3 | CX3: 1 | CY3: 3 | CZ3: no | DA3: no | DB3: 1 | DC3: 1 above 2^1 | DD3: 3 | DE3: 0 | DF3: 3 | DG3: 0 | DH3: odd | DI3: cMahea7zqjxrtgAbB7LSGbcQUr1uX1ojuat9jZodMN87KcLPVfXz | DJ3: mrzKXEpXfEDHk7vFS3LBXVXoa4YXFcCkje | DK3: tb1q0ht9tyks4vh7p5p904t340cr9nvahy7um9zdem | DL3: bc1pgxxyvcmdncdxs06cudd5yvmwwahaesaj6n3eu7st7x4sw9hrchaqjy33gs | DM3: 418c46636d9e1a683f58e35b42336e776fdcc3b2d4e39e7a0bf1ab0716e3c5fa | DN3: T33ydQRKp4FCW5LCLLUB7deioUMoveiwekdwUwyfRDeGakooUYaf | DO3: LWhKVQ3Nvs26Dp8ntcM6ybPEvHK6Y4VWZU | DP3: ltc1q0ht9tyks4vh7p5p904t340cr9nvahy7u4lr66c | DQ3: QNcdLVw8fHkixm6NNyN6nVwxKek4u7qrioRbQmjxac5TWoFhHVeV | DR3: DGcTmSgC9cgKW1dET4MNFLV5bCg7em2Bds | DS3: AvkwigGSWMMQSTRPhfidUim1MchFg2+ZsIYB8RO84Db5 | DT3: {=IF(B3="","",_xlfn.TEXTJOIN("",,HEX2BIN(MID(BQ3,_xlfn.SEQUENCE(40),1),4)))} -> 1110110001111110110011101101001011000101011111101101000100101001001010111100010011101011100110111111110100010011110010011111011101100000001110111100001100111000
A4: 3 | B4: 7 | C4: 111 | D4: 7 | E4: 3 | F4: 0.75 | G4: 3 | H4: 0 | I4: 100 | J4: 1 | K4: 13 | L4: 7 | M4: 7 | N4: 111 | O4: 7 | P4: 100 | Q4: 100 | R4: 0 | S4: 0700000000000000000000000000000000000000000000000000000000000000 | T4: 2.3333333 | U4: 1 | V4: KwDiBf89QgGbjEhKnhXJuH7LrciVrZi3qYjgd9M7rFU76rnZwVdz | W4: 5HpHagT65TZzG1PH3CSu63k8DbpvD8s5ip4nEB3kEsreBR6zCMU | X4: AAAAAAAAAAAAAAAAAAAAAAAAAAAAAAAAAAAAAAAAAAc= | Y4: 0101110111101101111110111111100111101010010110011001110111010100111000111100101001101010100000001011001100110011110001000111001011111101000010110011111101101001 | Z4: 2 | AA4: 2 | AB4: 93 | AC4: 0.57735027 | AD4: 0.57735027 | AE4: 1 | AF4: 7 | AG4: 7 | AH4: 7 | AI4: 2.8073549 | AJ4: 1.5849625 | AK4: 111 | AL4: 111 | AM4: 000 | AN4: 0 | AO4: 3 | AP4: 1 | AQ4: 1x3 | AR4: 1 | AS4: 7 | AT4: 7:1 | AU4: 1 | AV4: 2 | AW4: 0 | AX4: 7 | AY4: 7 | AZ4: 7 | BA4: 4 | BB4: 1 | BC4: 8 | BD4: 6 | BE4: 0x00 00 00 00 00 00 00 00 00 00 00 00 00 00 00 00 00 00 00 00 00 00 00 00 00 00 00 00 00 00 00 07 | BF4: 0,0,0,0,0,0,0,0,0,0,0,0,0,0,0,0,0,0,0,0,0,0,0,0,0,0,0,0,0,0,0,7 | BG4: ................................ | BH4: 0.0.0.7 | BI4: 25569 | BJ4: 7 | BK4: AAAAAAAAAAAAAAAAAAAAAAAAAAAAAAAAAAAAAAAAAAAAAAAAAADQ==== | BL4: AAAAAAAAAAAAAAAAAAAAAAAAAAAAAAAAAAAAAAAAAAc | BM4: fffffffffffffffffffffffffffffffebaaedce6af48a03bbfd25e8cd036413a | BN4: 5cbdf0646e5db4eaa398f365f2ea7a0e3d419b7e0330e39ce92bddedcac4f9bc | BO4: 6aebca40ba255960a3178d6d861a54dba813d0b813fde7b5a5082628087264da | BP4: 045cbdf0646e5db4eaa398f365f2ea7a0e3d419b7e0330e39ce92bddedcac4f9bc6aebca40ba255960a3178d6d861a54dba813d0b813fde7b5a5082628087264da | BQ4: 73ab19930b7c023b0c7e17da43649ca58a419999 | BR4: 1BYbgHpSKQCtMrQfwN6b6n5S718EJkEJ41 | BS4: 3BW9kFfY5TGhjVoRtxoijfjJvfggZgfNDX | BT4: bc1qthklh702txwafc72d2qtxv7ywt7sk0mfy3mw6y | BU4: 6.045318e-77 | BV4: 0101110010111101111100000110010001101110010111011011010011101010101000111001100011110011011001011111001011101010011110100000111000111101010000011001101101111110000000110011000011100011100111001110100100101011110111011110110111001010110001001111100110111100 | BW4: 2 | BX4: 2 | BY4: 0.57735027 | BZ4: 0.57735027 | CA4: =IF(B4="","",IF(A4<8,"",_xlfn.LET(_xlpm.n,A4,_xlpm.k,G4,_xlpm.R,AP4,_xlpm.mu,1+2*_xlpm.k*(_xlpm.n-_xlpm.k)/_xlpm.n,_xlpm.v,2*_xlpm.k*(_xlpm.n-_xlpm.k)*(2*_xlpm.k*(_xlpm.n-_xlpm.k)-_xlpm.n)/(_xlpm.n^2*(_xlpm.n-1)),IF(_xlpm.v<=0,"",(_xlpm.R-_xlpm.mu)/SQRT(_xlpm.v))))) | CB4: {=IF(B4="","",IF(A4<8,"",_xlfn.LET(_xlpm.b,--MID(C4,_xlfn.SEQUENCE(A4-1),1),_xlpm.c,--MID(C4,_xlfn.SEQUENCE(A4-1,,2),1),IFERROR(CORREL(_xlpm.b,_xlpm.c),""))))} | CC4: =IF(B4="","",LOG(A4,2)) -> 1.5849625 | CD4: =IF(B4="","",MAX(AN4,AO4)-CC4) -> 1.4150375 | CE4: {=IF(B4="","",IF(LEN(B4)<16,"",_xlfn.LET(_xlpm.d,MID("0123456789abcdef",_xlfn.SEQUENCE(16),1),_xlpm.c,LEN(B4)-LEN(SUBSTITUTE(B4,_xlpm.d,"")),_xlpm.ex,LEN(B4)/16,SUM((_xlpm.c-_xlpm.ex)^2/_xlpm.ex))))} | CF4: =IF(CE4="","",_xlfn.CHISQ.DIST.RT(CE4,15)) | CG4: {=IF(OR(B4="",B3=""),"",_xlfn.LET(_xlpm.a,C4,_xlpm.b,REPT("0",A4-LEN(C3))&C3,_xlpm.m,MID(_xlpm.a,_xlfn.SEQUENCE(A4),1)=MID(_xlpm.b,_xlfn.SEQUENCE(A4),1),IFERROR(MATCH(FALSE,_xlpm.m,0)-1,A4)))} -> 0 | CH4: {=IF(OR(B4="",B3=""),"",_xlfn.LET(_xlpm.a,C4,_xlpm.b,REPT("0",A4-LEN(C3))&C3,_xlpm.n,A4,_xlpm.m,MID(_xlpm.a,_xlfn.SEQUENCE(_xlpm.n,,_xlpm.n,-1),1)=MID(_xlpm.b,_xlfn.SEQUENCE(_xlpm.n,,_xlpm.n,-1),1),IFERROR(MATCH(FALSE,_xlpm.m,0)-1,_xlpm.n)))} -> 2 | CI4: =IF(OR(B4="",B3=""),"",F4-F3) -> 0.25 | CJ4: =IF(OR(B4="",B3=""),"",IFERROR(FIND(B3,B4)>0,FALSE)) -> FALSE | CK4: =IF(OR(B4="",B3=""),"",IFERROR(FIND(C3,C4)>0,FALSE)) -> TRUE | CL4: =IF(OR(B4="",B3=""),"",IFERROR(FIND(C3,C4),"")) -> 1 | CM4: {=IF(OR(B4="",B3=""),"",_xlfn.LET(_xlpm.pv,D3,_xlpm.ra,BIGSUB(D4,_xlpm.pv),_xlpm.rb,BIGSUB(_xlpm.ra,_xlpm.pv),_xlpm.rc,BIGSUB(_xlpm.rb,_xlpm.pv),IF(LEFT(_xlpm.rb,1)="-",_xlpm.ra,IF(LEFT(_xlpm.rc,1)="-",_xlpm.rb,_xlpm.rc))))} -> 1 | CN4: =IF(B4="","",F4-0.5) -> 0.25 | CO4: {=IF(B4="","",_xlfn.TEXTJOIN("",,MID(B4,_xlfn.SEQUENCE(LEN(B4),,LEN(B4),-1),1)))} -> 7 | CP4: {=IF(B4="","",BASE2DEC(CO4,16))} -> 7 | CQ4: =IF(B4="","",IF(AND(LEN(B4)<16,LEN(B4)=LEN(SUBSTITUTE(SUBSTITUTE(SUBSTITUTE(SUBSTITUTE(SUBSTITUTE(SUBSTITUTE(B4,"a",""),"b",""),"c",""),"d",""),"e",""),"f",""))),--B4,"")) -> 7 | CR4: {=IF(B4="","",IF(LEN(D4)<=15,BASE2DEC(D4,16),""))} -> 7 | CS4: {=IF(B4="","",_xlfn.LET(_xlpm.p,REPT("0",MOD(-LEN(B4),4))&B4,_xlfn.TEXTJOIN(" ",,MID(_xlpm.p,_xlfn.SEQUENCE(LEN(_xlpm.p)/4,,1,4),4))))} -> 0007 | CT4: {=IF(B4="","",UPPER(_xlfn.LET(_xlpm.p,REPT("0",64-LEN(B4))&B4,_xlfn.TEXTJOIN(" ",,MID(_xlpm.p,_xlfn.SEQUENCE(8,,1,8),8)))))} -> 00000000 00000000 00000000 00000000 00000000 00000000 00000000 00000007 | CU4: {=IF(B4="","",IF(LEN(D4)<=6,_xlfn.LET(_xlpm.n,VALUE(D4),_xlpm.ones,{"","one","two","three","four","five","six","seven","eight","nine","ten","eleven","twelve","thirteen","fourteen","fifteen","sixteen","seventeen","eighteen","nineteen"},_xlpm.tens,{"","","twenty","thirty","forty","fifty","sixty","seventy","eighty","ninety"},_xlpm.f,_xlfn.LAMBDA(_xlpm.x,TRIM(IF(_xlpm.x>=100,INDEX(_xlpm.ones,INT(_xlpm.x/100)+1)&" hundred ","")&IF(MOD(_xlpm.x,100)<20,INDEX(_xlpm.ones,MOD(_xlpm.x,100)+1),INDEX(_xlpm.tens,INT(MOD(_xlpm.x,100)/10)+1)&IF(MOD(_xlpm.x,10)>0,"-"&INDEX(_xlpm.ones,MOD(_xlpm.x,10)+1),"")))),TRIM(IF(_xlpm.n>=1000,_xlpm.f(INT(_xlpm.n/1000))&" thousand ","")&IF(MOD(_xlpm.n,1000)>0,_xlpm.f(MOD(_xlpm.n,1000)),""))),""))} -> seven | CV4: yes | CW4: 7 | CX4: 1 | CY4: 7 | CZ4: no | DA4: no | DB4: 3 | DC4: 1 below 2^3 | DD4: 8 | DE4: 1 | DF4: 6 | DG4: 1 | DH4: odd | DI4: cMahea7zqjxrtgAbB7LSGbcQUr1uX1ojuat9jZodMN87MbvFSpLf | DJ4: mp5cELDJZ2pUNYrF1i5dCyT34j48UzaKRU | DK4: tb1qthklh702txwafc72d2qtxv7ywt7sk0mfwhqaph | DL4: bc1pr896td3mmjl5vc57mutumgfmeet8hyzy9w6zr6hg5vhrtppevlpsp3x3nm | DM4: 19cba5b63bdcbf46629edf17cda13bce567b90442bb421eae8a32e35843967c3 | DN4: T33ydQRKp4FCW5LCLLUB7deioUMoveiwekdwUwyfRDeGckMREisC | DO4: LTncCVS9pfdGrF4nUH6Yf5JUQwphhqVq54 | DP4: ltc1qthklh702txwafc72d2qtxv7ywt7sk0mfqdp2z5 | DQ4: QNcdLVw8fHkixm6NNyN6nVwxKek4u7qrioRbQmjxac5TYnjVc8Ke | DR4: DDhkUY4y3RHW8SZE2j6ovpQK5sBiv5gurH | DS4: Aly98GRuXbTqo5jzZfLqeg49QZt+AzDjnOkr3e3KxPm8 | DT4: {=IF(B4="","",_xlfn.TEXTJOIN("",,HEX2BIN(MID(BQ4,_xlfn.SEQUENCE(40),1),4)))} -> 0111001110101011000110011001001100001011011111000000001000111011000011000111111000010111110110100100001101100100100111001010010110001010010000011001100110011001
A5: 4 | B5: 8 | C5: 1000 | D5: 8 | E5: 0 | F5: 0 | G5: 1 | H5: 3 | I5: 1111 | J5: 4 | K5: 20 | L5: 10 | M5: 8 | N5: 0001 | O5: 1 | P5: 1100 | Q5: 1111 | R5: 7 | S5: 0800000000000000000000000000000000000000000000000000000000000000 | T5: 1.1428571 | U5: 0.25 | V5: KwDiBf89QgGbjEhKnhXJuH7LrciVrZi3qYjgd9M7rFU77MfhviY5 | W5: 5HpHagT65TZzG1PH3CSu63k8DbpvD8s5ip4nEB3kEsreBbMaQX1 | X5: AAAAAAAAAAAAAAAAAAAAAAAAAAAAAAAAAAAAAAAAAAg= | Y5: 1001011001010010110110000110101111101101111101000011101011010010011001000011011000101110011011100110111010111010011011101011011101100100010100001000000100100111 | Z5: 4 | AA5: 1 | AB5: 84 | AC5: 2 | AD5: -1 | AE5: 1 | AF5: 8 | AG5: 8 | AH5: 8 | AI5: 3 | AK5: 0001 | AL5: 0100 | AM5: 0111 | AN5: 3 | AO5: 1 | AP5: 2 | AQ5: 1x1,0x3 | AR5: 1 | AS5: 8 | AT5: 8:1 | AU5: 2 | AV5: 3 | AW5: 1 | AX5: 8 | AY5: 8 | AZ5: 8 | BA5: 1 | BB5: -6 | BC5: 9 | BD5: 7 | BE5: 0x00 00 00 00 00 00 00 00 00 00 00 00 00 00 00 00 00 00 00 00 00 00 00 00 00 00 00 00 00 00 00 08 | BF5: 0,0,0,0,0,0,0,0,0,0,0,0,0,0,0,0,0,0,0,0,0,0,0,0,0,0,0,0,0,0,0,8 | BG5: ................................ | BH5: 0.0.0.8 | BI5: 25569 | BJ5: 8 | BK5: AAAAAAAAAAAAAAAAAAAAAAAAAAAAAAAAAAAAAAAAAAAAAAAAAAEA==== | BL5: AAAAAAAAAAAAAAAAAAAAAAAAAAAAAAAAAAAAAAAAAAg | BM5: fffffffffffffffffffffffffffffffebaaedce6af48a03bbfd25e8cd0364139 | BN5: 2f01e5e15cca351daff3843fb70f3c2f0a1bdd05e5af888a67784ef3e10a2a01 | BO5: 5c4da8a741539949293d082a132d13b4c2e213d6ba5b7617b5da2cb76cbde904 | BP5: 042f01e5e15cca351daff3843fb70f3c2f0a1bdd05e5af888a67784ef3e10a2a015c4da8a741539949293d082a132d13b4c2e213d6ba5b7617b5da2cb76cbde904 | BQ5: be5fdeb54c869d582cf796c34e28b4d21813ffa6 | BR5: 1JMcEcKXQ7xA7JLAMPsBmHz68bzugYtdrv | BS5: 3PNNDgsXkAwe6jZScfShL3KapB6FhFePRH | BT5: bc1qjefds6ld7sadyepk9ehxawnwkaj9pqf8xuq2eg | BU5: 6.9089348e-77 | BV5: 0010111100000001111001011110000101011100110010100011010100011101101011111111001110000100001111111011011100001111001111000010111100001010000110111101110100000101111001011010111110001000100010100110011101111000010011101111001111100001000010100010101000000001 | BW5: 2 | BX5: 2 | BY5: 0 | BZ5: 0 | CA5: =IF(B5="","",IF(A5<8,"",_xlfn.LET(_xlpm.n,A5,_xlpm.k,G5,_xlpm.R,AP5,_xlpm.mu,1+2*_xlpm.k*(_xlpm.n-_xlpm.k)/_xlpm.n,_xlpm.v,2*_xlpm.k*(_xlpm.n-_xlpm.k)*(2*_xlpm.k*(_xlpm.n-_xlpm.k)-_xlpm.n)/(_xlpm.n^2*(_xlpm.n-1)),IF(_xlpm.v<=0,"",(_xlpm.R-_xlpm.mu)/SQRT(_xlpm.v))))) | CB5: {=IF(B5="","",IF(A5<8,"",_xlfn.LET(_xlpm.b,--MID(C5,_xlfn.SEQUENCE(A5-1),1),_xlpm.c,--MID(C5,_xlfn.SEQUENCE(A5-1,,2),1),IFERROR(CORREL(_xlpm.b,_xlpm.c),""))))} | CC5: =IF(B5="","",LOG(A5,2)) -> 2 | CD5: =IF(B5="","",MAX(AN5,AO5)-CC5) -> 1 | CE5: {=IF(B5="","",IF(LEN(B5)<16,"",_xlfn.LET(_xlpm.d,MID("0123456789abcdef",_xlfn.SEQUENCE(16),1),_xlpm.c,LEN(B5)-LEN(SUBSTITUTE(B5,_xlpm.d,"")),_xlpm.ex,LEN(B5)/16,SUM((_xlpm.c-_xlpm.ex)^2/_xlpm.ex))))} | CF5: =IF(CE5="","",_xlfn.CHISQ.DIST.RT(CE5,15)) | CG5: {=IF(OR(B5="",B4=""),"",_xlfn.LET(_xlpm.a,C5,_xlpm.b,REPT("0",A5-LEN(C4))&C4,_xlpm.m,MID(_xlpm.a,_xlfn.SEQUENCE(A5),1)=MID(_xlpm.b,_xlfn.SEQUENCE(A5),1),IFERROR(MATCH(FALSE,_xlpm.m,0)-1,A5)))} -> 0 | CH5: {=IF(OR(B5="",B4=""),"",_xlfn.LET(_xlpm.a,C5,_xlpm.b,REPT("0",A5-LEN(C4))&C4,_xlpm.n,A5,_xlpm.m,MID(_xlpm.a,_xlfn.SEQUENCE(_xlpm.n,,_xlpm.n,-1),1)=MID(_xlpm.b,_xlfn.SEQUENCE(_xlpm.n,,_xlpm.n,-1),1),IFERROR(MATCH(FALSE,_xlpm.m,0)-1,_xlpm.n)))} -> 0 | CI5: =IF(OR(B5="",B4=""),"",F5-F4) -> -0.75 | CJ5: =IF(OR(B5="",B4=""),"",IFERROR(FIND(B4,B5)>0,FALSE)) -> FALSE | CK5: =IF(OR(B5="",B4=""),"",IFERROR(FIND(C4,C5)>0,FALSE)) -> FALSE | CL5: =IF(OR(B5="",B4=""),"",IFERROR(FIND(C4,C5),"")) | CM5: {=IF(OR(B5="",B4=""),"",_xlfn.LET(_xlpm.pv,D4,_xlpm.ra,BIGSUB(D5,_xlpm.pv),_xlpm.rb,BIGSUB(_xlpm.ra,_xlpm.pv),_xlpm.rc,BIGSUB(_xlpm.rb,_xlpm.pv),IF(LEFT(_xlpm.rb,1)="-",_xlpm.ra,IF(LEFT(_xlpm.rc,1)="-",_xlpm.rb,_xlpm.rc))))} -> 1 | CN5: =IF(B5="","",F5-0.5) -> -0.5 | CO5: {=IF(B5="","",_xlfn.TEXTJOIN("",,MID(B5,_xlfn.SEQUENCE(LEN(B5),,LEN(B5),-1),1)))} -> 8 | CP5: {=IF(B5="","",BASE2DEC(CO5,16))} -> 8 | CQ5: =IF(B5="","",IF(AND(LEN(B5)<16,LEN(B5)=LEN(SUBSTITUTE(SUBSTITUTE(SUBSTITUTE(SUBSTITUTE(SUBSTITUTE(SUBSTITUTE(B5,"a",""),"b",""),"c",""),"d",""),"e",""),"f",""))),--B5,"")) -> 8 | CR5: {=IF(B5="","",IF(LEN(D5)<=15,BASE2DEC(D5,16),""))} -> 8 | CS5: {=IF(B5="","",_xlfn.LET(_xlpm.p,REPT("0",MOD(-LEN(B5),4))&B5,_xlfn.TEXTJOIN(" ",,MID(_xlpm.p,_xlfn.SEQUENCE(LEN(_xlpm.p)/4,,1,4),4))))} -> 0008 | CT5: {=IF(B5="","",UPPER(_xlfn.LET(_xlpm.p,REPT("0",64-LEN(B5))&B5,_xlfn.TEXTJOIN(" ",,MID(_xlpm.p,_xlfn.SEQUENCE(8,,1,8),8)))))} -> 00000000 00000000 00000000 00000000 00000000 00000000 00000000 00000008 | CU5: {=IF(B5="","",IF(LEN(D5)<=6,_xlfn.LET(_xlpm.n,VALUE(D5),_xlpm.ones,{"","one","two","three","four","five","six","seven","eight","nine","ten","eleven","twelve","thirteen","fourteen","fifteen","sixteen","seventeen","eighteen","nineteen"},_xlpm.tens,{"","","twenty","thirty","forty","fifty","sixty","seventy","eighty","ninety"},_xlpm.f,_xlfn.LAMBDA(_xlpm.x,TRIM(IF(_xlpm.x>=100,INDEX(_xlpm.ones,INT(_xlpm.x/100)+1)&" hundred ","")&IF(MOD(_xlpm.x,100)<20,INDEX(_xlpm.ones,MOD(_xlpm.x,100)+1),INDEX(_xlpm.tens,INT(MOD(_xlpm.x,100)/10)+1)&IF(MOD(_xlpm.x,10)>0,"-"&INDEX(_xlpm.ones,MOD(_xlpm.x,10)+1),"")))),TRIM(IF(_xlpm.n>=1000,_xlpm.f(INT(_xlpm.n/1000))&" thousand ","")&IF(MOD(_xlpm.n,1000)>0,_xlpm.f(MOD(_xlpm.n,1000)),""))),""))} -> eight | CV5: no | CW5: 2 | CX5: 1 | CY5: 2 | CZ5: no | DA5: yes | DB5: 3 | DC5: 0 below 2^3 | DD5: 8 | DE5: 0 | DF5: 6 | DG5: 2 | DH5: even | DI5: cMahea7zqjxrtgAbB7LSGbcQUr1uX1ojuat9jZodMN87N6jaiCXQ | DJ5: muDnu2ZLjxJMxmokQNWUfXbv5692bmye8C | DK5: tb1qjefds6ld7sadyepk9ehxawnwkaj9pqf8v6mezm | DL5: bc1p5ju3f0m0dz3y4hgynde804krzz2grxr8chytzgew4fxmk5lunzlqwe8xsx | DM5: a4b914bf6f68a24add049b7277d6c31094819867c5c8b1232eaa4dbb53fc98be | DN5: T33ydQRKp4FCW5LCLLUB7deioUMoveiwekdwUwyfRDeGdFCPBp4F | DO5: LYvnsBnC1b7ASU2HrwXQ7dTMRJubqCryRA | DP5: ltc1qjefds6ld7sadyepk9ehxawnwkaj9pqf8zq6wpc | DQ5: QNcdLVw8fHkixm6NNyN6nVwxKek4u7qrioRbQmjxac5TZHeZtgye | DR5: DJqw9ER1ELmPifWjRPXfPNZC6EGcyShGGH | DS5: Ai8B5eFcyjUdr/OEP7cPPC8KG90F5a+Iimd4TvPhCioB | DT5: {=IF(B5="","",_xlfn.TEXTJOIN("",,HEX2BIN(MID(BQ5,_xlfn.SEQUENCE(40),1),4)))} -> 1011111001011111110111101011010101001100100001101001110101011000001011001111011110010110110000110100111000101000101101001101001000011000000100111111111110100110
A6: 5 | B6: 15 | C6: 10101 | D6: 21 | E6: 5 | F6: 0.3125 | G6: 3 | H6: 0 | I6: 11101 | J6: 4 | K6: 111 | L6: 25 | M6: l | N6: 10101 | O6: 21 | P6: 11111 | Q6: 11010 | R6: 10 | S6: 1500000000000000000000000000000000000000000000000000000000000000 | T6: 2.625 | U6: 0.6 | V6: KwDiBf89QgGbjEhKnhXJuH7LrciVrZi3qYjgd9M7rFU7Dq8Au4Pv | W6: 5HpHagT65TZzG1PH3CSu63k8DbpvD8s5ip4nEB3kEsreD437Nay | X6: AAAAAAAAAAAAAAAAAAAAAAAAAAAAAAAAAAAAAAAAABU= | Y6: 1000111110011101111111110011100110101000000111101110010010101011110010111010110100101010110110001011101011111111111100001001000001000001010110100010101111101000 | Z6: 4 | AA6: 1 | AB6: 91 | AC6: 1.3416408 | AD6: -1.3416408 | AE6: 2 | AF6: 3 | AG6: 3 | AH6: 12 | AI6: 4.3923174 | AJ6: 2.3219281 | AK6: 01011 | AL6: 11010 | AM6: 01010 | AN6: 1 | AO6: 1 | AP6: 5 | AQ6: 1x1,0x1,1x1,0x1,1x1 | AR6: 2 | AS6: 1 | AT6: 1:1 5:1 | AU6: 0 | AV6: 1 | AW6: 0 | AX6: 10 | AY6: 21 | AZ6: 21 | BA6: 13 | BB6: 5 | BC6: 22 | BD6: 20 | BE6: 0x00 00 00 00 00 00 00 00 00 00 00 00 00 00 00 00 00 00 00 00 00 00 00 00 00 00 00 00 00 00 00 15 | BF6: 0,0,0,0,0,0,0,0,0,0,0,0,0,0,0,0,0,0,0,0,0,0,0,0,0,0,0,0,0,0,0,21 | BG6: ................................ | BH6: 0.0.0.21 | BI6: 25569 | BJ6: l | BK6: AAAAAAAAAAAAAAAAAAAAAAAAAAAAAAAAAAAAAAAAAAAAAAAAAAKQ==== | BL6: AAAAAAAAAAAAAAAAAAAAAAAAAAAAAAAAAAAAAAAAABU | BM6: fffffffffffffffffffffffffffffffebaaedce6af48a03bbfd25e8cd036412c | BN6: 352bbf4a4cdd12564f93fa332ce333301d9ad40271f8107181340aef25be59d5 | BO6: 321eb4075348f534d59c18259dda3e1f4a1b3b2e71b1039c67bd3d8bcf81998c | BP6: 04352bbf4a4cdd12564f93fa332ce333301d9ad40271f8107181340aef25be59d5321eb4075348f534d59c18259dda3e1f4a1b3b2e71b1039c67bd3d8bcf81998c | BQ6: 61f5b379403bcfdac1c05c3746768a14855e6519 | BR6: 19vxtDbLMNasSpbAEZd7va5Qge6d2zYWbp | BS6: 38xPY27A6fiRXHSDRbRkLfV2xQb7UmKpXv | BT6: bc1q37wl7wdgrmj2hjad9tvt4llsjpq452lgkcskpy | BU6: 1.8135954e-76 | BV6: 0011010100101011101111110100101001001100110111010001001001010110010011111001001111111010001100110010110011100011001100110011000000011101100110101101010000000010011100011111100000010000011100011000000100110100000010101110111100100101101111100101100111010101 | BW6: 0 | BX6: 3 | BY6: -2.236068 | BZ6: 0.4472136 | CA6: =IF(B6="","",IF(A6<8,"",_xlfn.LET(_xlpm.n,A6,_xlpm.k,G6,_xlpm.R,AP6,_xlpm.mu,1+2*_xlpm.k*(_xlpm.n-_xlpm.k)/_xlpm.n,_xlpm.v,2*_xlpm.k*(_xlpm.n-_xlpm.k)*(2*_xlpm.k*(_xlpm.n-_xlpm.k)-_xlpm.n)/(_xlpm.n^2*(_xlpm.n-1)),IF(_xlpm.v<=0,"",(_xlpm.R-_xlpm.mu)/SQRT(_xlpm.v))))) | CB6: {=IF(B6="","",IF(A6<8,"",_xlfn.LET(_xlpm.b,--MID(C6,_xlfn.SEQUENCE(A6-1),1),_xlpm.c,--MID(C6,_xlfn.SEQUENCE(A6-1,,2),1),IFERROR(CORREL(_xlpm.b,_xlpm.c),""))))} | CC6: =IF(B6="","",LOG(A6,2)) -> 2.3219281 | CD6: =IF(B6="","",MAX(AN6,AO6)-CC6) -> -1.3219281 | CE6: {=IF(B6="","",IF(LEN(B6)<16,"",_xlfn.LET(_xlpm.d,MID("0123456789abcdef",_xlfn.SEQUENCE(16),1),_xlpm.c,LEN(B6)-LEN(SUBSTITUTE(B6,_xlpm.d,"")),_xlpm.ex,LEN(B6)/16,SUM((_xlpm.c-_xlpm.ex)^2/_xlpm.ex))))} | CF6: =IF(CE6="","",_xlfn.CHISQ.DIST.RT(CE6,15)) | CG6: {=IF(OR(B6="",B5=""),"",_xlfn.LET(_xlpm.a,C6,_xlpm.b,REPT("0",A6-LEN(C5))&C5,_xlpm.m,MID(_xlpm.a,_xlfn.SEQUENCE(A6),1)=MID(_xlpm.b,_xlfn.SEQUENCE(A6),1),IFERROR(MATCH(FALSE,_xlpm.m,0)-1,A6)))} -> 0 | CH6: {=IF(OR(B6="",B5=""),"",_xlfn.LET(_xlpm.a,C6,_xlpm.b,REPT("0",A6-LEN(C5))&C5,_xlpm.n,A6,_xlpm.m,MID(_xlpm.a,_xlfn.SEQUENCE(_xlpm.n,,_xlpm.n,-1),1)=MID(_xlpm.b,_xlfn.SEQUENCE(_xlpm.n,,_xlpm.n,-1),1),IFERROR(MATCH(FALSE,_xlpm.m,0)-1,_xlpm.n)))} -> 0 | CI6: =IF(OR(B6="",B5=""),"",F6-F5) -> 0.3125 | CJ6: =IF(OR(B6="",B5=""),"",IFERROR(FIND(B5,B6)>0,FALSE)) -> FALSE | CK6: =IF(OR(B6="",B5=""),"",IFERROR(FIND(C5,C6)>0,FALSE)) -> FALSE | CL6: =IF(OR(B6="",B5=""),"",IFERROR(FIND(C5,C6),"")) | CM6: {=IF(OR(B6="",B5=""),"",_xlfn.LET(_xlpm.pv,D5,_xlpm.ra,BIGSUB(D6,_xlpm.pv),_xlpm.rb,BIGSUB(_xlpm.ra,_xlpm.pv),_xlpm.rc,BIGSUB(_xlpm.rb,_xlpm.pv),IF(LEFT(_xlpm.rb,1)="-",_xlpm.ra,IF(LEFT(_xlpm.rc,1)="-",_xlpm.rb,_xlpm.rc))))} -> 5 | CN6: =IF(B6="","",F6-0.5) -> -0.1875 | CO6: {=IF(B6="","",_xlfn.TEXTJOIN("",,MID(B6,_xlfn.SEQUENCE(LEN(B6),,LEN(B6),-1),1)))} -> 51 | CP6: {=IF(B6="","",BASE2DEC(CO6,16))} -> 81 | CQ6: =IF(B6="","",IF(AND(LEN(B6)<16,LEN(B6)=LEN(SUBSTITUTE(SUBSTITUTE(SUBSTITUTE(SUBSTITUTE(SUBSTITUTE(SUBSTITUTE(B6,"a",""),"b",""),"c",""),"d",""),"e",""),"f",""))),--B6,"")) -> 15 | CR6: {=IF(B6="","",IF(LEN(D6)<=15,BASE2DEC(D6,16),""))} -> 33 | CS6: {=IF(B6="","",_xlfn.LET(_xlpm.p,REPT("0",MOD(-LEN(B6),4))&B6,_xlfn.TEXTJOIN(" ",,MID(_xlpm.p,_xlfn.SEQUENCE(LEN(_xlpm.p)/4,,1,4),4))))} -> 0015 | CT6: {=IF(B6="","",UPPER(_xlfn.LET(_xlpm.p,REPT("0",64-LEN(B6))&B6,_xlfn.TEXTJOIN(" ",,MID(_xlpm.p,_xlfn.SEQUENCE(8,,1,8),8)))))} -> 00000000 00000000 00000000 00000000 00000000 00000000 00000000 00000015 | CU6: {=IF(B6="","",IF(LEN(D6)<=6,_xlfn.LET(_xlpm.n,VALUE(D6),_xlpm.ones,{"","one","two","three","four","five","six","seven","eight","nine","ten","eleven","twelve","thirteen","fourteen","fifteen","sixteen","seventeen","eighteen","nineteen"},_xlpm.tens,{"","","twenty","thirty","forty","fifty","sixty","seventy","eighty","ninety"},_xlpm.f,_xlfn.LAMBDA(_xlpm.x,TRIM(IF(_xlpm.x>=100,INDEX(_xlpm.ones,INT(_xlpm.x/100)+1)&" hundred ","")&IF(MOD(_xlpm.x,100)<20,INDEX(_xlpm.ones,MOD(_xlpm.x,100)+1),INDEX(_xlpm.tens,INT(MOD(_xlpm.x,100)/10)+1)&IF(MOD(_xlpm.x,10)>0,"-"&INDEX(_xlpm.ones,MOD(_xlpm.x,10)+1),"")))),TRIM(IF(_xlpm.n>=1000,_xlpm.f(INT(_xlpm.n/1000))&" thousand ","")&IF(MOD(_xlpm.n,1000)>0,_xlpm.f(MOD(_xlpm.n,1000)),""))),""))} -> twenty-one | CV6: no | CW6: 3 | CX6: 2 | CY6: 3 × 7 | CZ6: no | DA6: no | DB6: 4 | DC6: 5 above 2^4 | DD6: 21 | DE6: 0 | DF6: 21 | DG6: 0 | DH6: odd | DI6: cMahea7zqjxrtgAbB7LSGbcQUr1uX1ojuat9jZodMN87UaEpLrnP | DJ6: mtcLCJpBX3Yks7H9PhRoTXekh7fhD5LcxK | DK6: tb1q37wl7wdgrmj2hjad9tvt4llsjpq452lgu7t96h | DL6: bc1pssmuqnp7u3eavjvqph0j2f36ar4ejtu7yreykq9vuw528sskwcnqh6t7hx | DM6: 8437c04c3ee473d649800ddf25263ae8eb992f9e20f24b00ace3a8a3c2167626 | DN6: T33ydQRKp4FCW5LCLLUB7deioUMoveiwekdwUwyfRDeGjik62hs1 | DO6: LYKLAU32ngMZLoVgrGSiudWC3LSGTLHNn8 | DP6: ltc1q37wl7wdgrmj2hjad9tvt4llsjpq452lgjy2je5 | DQ6: QNcdLVw8fHkixm6NNyN6nVwxKek4u7qrioRbQmjxac5TfmAaoycD | DR6: DJEUSWfr1S1nczz8QiSzBNc2iFoHappwyx | DS6: AjUrv0pM3RJWT5P6MyzjMzAdmtQCcfgQcYE0Cu8lvlnV | DT6: {=IF(B6="","",_xlfn.TEXTJOIN("",,HEX2BIN(MID(BQ6,_xlfn.SEQUENCE(40),1),4)))} -> 0110000111110101101100110111100101000000001110111100111111011010110000011100000001011100001101110100011001110110100010100001010010000101010111100110010100011001
A7: 6 | B7: 31 | C7: 110001 | D7: 49 | E7: 17 | F7: 0.53125 | G7: 3 | H7: 0 | I7: 100100 | J7: 2 | K7: 301 | L7: 61 | M7: 1h | N7: 100011 | O7: 35 | P7: 101001 | Q7: 101110 | R7: 14 | S7: 3100000000000000000000000000000000000000000000000000000000000000 | T7: 2.3333333 | U7: 0.5 | V7: KwDiBf89QgGbjEhKnhXJuH7LrciVrZi3qYjgd9M7rFU7Tmu6qHxS | W7: 5HpHagT65TZzG1PH3CSu63k8DbpvD8s5ip4nEB3kEsreGAk6qMH | X7: AAAAAAAAAAAAAAAAAAAAAAAAAAAAAAAAAAAAAAAAADE= | Y7: 1111100100111110110000110100111010011110001101001010100011111000111111110111110101100000000011001101101011011000001100000100011110110001101111001011010001011100 | Z7: 4 | AA7: 4 | AB7: 86 | AC7: 0.81649658 | AD7: 0.81649658 | AE7: 2 | AF7: 13 | AG7: 4 | AH7: 94 | AI7: 5.6147098 | AJ7: 4.0874628 | AK7: 100011 | AL7: 111000 | AM7: 001110 | AN7: 3 | AO7: 2 | AP7: 3 | AQ7: 1x2,0x3,1x1 | AR7: 2 | AS7: 1 | AT7: 1:1 3:1 | AU7: 1 | AV7: 4 | AW7: 0 | AX7: 5 | AY7: 49 | AZ7: 49 | BA7: 28 | BB7: 7 | BC7: 50 | BD7: 48 | BE7: 0x00 00 00 00 00 00 00 00 00 00 00 00 00 00 00 00 00 00 00 00 00 00 00 00 00 00 00 00 00 00 00 31 | BF7: 0,0,0,0,0,0,0,0,0,0,0,0,0,0,0,0,0,0,0,0,0,0,0,0,0,0,0,0,0,0,0,49 | BG7: ...............................1 | BH7: 0.0.0.49 | BI7: 25569.001 | BJ7: 1d | BK7: AAAAAAAAAAAAAAAAAAAAAAAAAAAAAAAAAAAAAAAAAAAAAAAAAAYQ==== | BL7: AAAAAAAAAAAAAAAAAAAAAAAAAAAAAAAAAAAAAAAAADE | BM7: fffffffffffffffffffffffffffffffebaaedce6af48a03bbfd25e8cd0364110 | BN7: f2dac991cc4ce4b9ea44887e5c7c0bce58c80074ab9d4dbaeb28531b7739f530 | BO7: e0dedc9b3b2f8dad4da1f32dec2531df9eb5fbeb0598e4fd1a117dba703a3c37 | BP7: 04f2dac991cc4ce4b9ea44887e5c7c0bce58c80074ab9d4dbaeb28531b7739f530e0dedc9b3b2f8dad4da1f32dec2531df9eb5fbeb0598e4fd1a117dba703a3c37 | BQ7: 50178322b20379db4a958958ef4988db6d9e9e20 | BR7: 18JVE1MSS7a2NEhtHJkxhwgvT4hLQYBw3w | BS7: 3BkXwT6CK1dFEVSGbJHzrwNisUGhuWBRwd | BT7: bc1qlylvxn57xj503lmavqxd4kpsg7cmedzuugem3h | BU7: 4.2317226e-76 | BV7: 1111001011011010110010011001000111001100010011001110010010111001111010100100010010001000011111100101110001111100000010111100111001011000110010000000000001110100101010111001110101001101101110101110101100101000010100110001101101110111001110011111010100110000 | BW7: 1 | BX7: 3 | BY7: -1.6329932 | BZ7: 0 | CA7: =IF(B7="","",IF(A7<8,"",_xlfn.LET(_xlpm.n,A7,_xlpm.k,G7,_xlpm.R,AP7,_xlpm.mu,1+2*_xlpm.k*(_xlpm.n-_xlpm.k)/_xlpm.n,_xlpm.v,2*_xlpm.k*(_xlpm.n-_xlpm.k)*(2*_xlpm.k*(_xlpm.n-_xlpm.k)-_xlpm.n)/(_xlpm.n^2*(_xlpm.n-1)),IF(_xlpm.v<=0,"",(_xlpm.R-_xlpm.mu)/SQRT(_xlpm.v))))) | CB7: {=IF(B7="","",IF(A7<8,"",_xlfn.LET(_xlpm.b,--MID(C7,_xlfn.SEQUENCE(A7-1),1),_xlpm.c,--MID(C7,_xlfn.SEQUENCE(A7-1,,2),1),IFERROR(CORREL(_xlpm.b,_xlpm.c),""))))} | CC7: =IF(B7="","",LOG(A7,2)) -> 2.5849625 | CD7: =IF(B7="","",MAX(AN7,AO7)-CC7) -> 0.4150375 | CE7: {=IF(B7="","",IF(LEN(B7)<16,"",_xlfn.LET(_xlpm.d,MID("0123456789abcdef",_xlfn.SEQUENCE(16),1),_xlpm.c,LEN(B7)-LEN(SUBSTITUTE(B7,_xlpm.d,"")),_xlpm.ex,LEN(B7)/16,SUM((_xlpm.c-_xlpm.ex)^2/_xlpm.ex))))} | CF7: =IF(CE7="","",_xlfn.CHISQ.DIST.RT(CE7,15)) | CG7: {=IF(OR(B7="",B6=""),"",_xlfn.LET(_xlpm.a,C7,_xlpm.b,REPT("0",A7-LEN(C6))&C6,_xlpm.m,MID(_xlpm.a,_xlfn.SEQUENCE(A7),1)=MID(_xlpm.b,_xlfn.SEQUENCE(A7),1),IFERROR(MATCH(FALSE,_xlpm.m,0)-1,A7)))} -> 0 | CH7: {=IF(OR(B7="",B6=""),"",_xlfn.LET(_xlpm.a,C7,_xlpm.b,REPT("0",A7-LEN(C6))&C6,_xlpm.n,A7,_xlpm.m,MID(_xlpm.a,_xlfn.SEQUENCE(_xlpm.n,,_xlpm.n,-1),1)=MID(_xlpm.b,_xlfn.SEQUENCE(_xlpm.n,,_xlpm.n,-1),1),IFERROR(MATCH(FALSE,_xlpm.m,0)-1,_xlpm.n)))} -> 2 | CI7: =IF(OR(B7="",B6=""),"",F7-F6) -> 0.21875 | CJ7: =IF(OR(B7="",B6=""),"",IFERROR(FIND(B6,B7)>0,FALSE)) -> FALSE | CK7: =IF(OR(B7="",B6=""),"",IFERROR(FIND(C6,C7)>0,FALSE)) -> FALSE | CL7: =IF(OR(B7="",B6=""),"",IFERROR(FIND(C6,C7),"")) | CM7: {=IF(OR(B7="",B6=""),"",_xlfn.LET(_xlpm.pv,D6,_xlpm.ra,BIGSUB(D7,_xlpm.pv),_xlpm.rb,BIGSUB(_xlpm.ra,_xlpm.pv),_xlpm.rc,BIGSUB(_xlpm.rb,_xlpm.pv),IF(LEFT(_xlpm.rb,1)="-",_xlpm.ra,IF(LEFT(_xlpm.rc,1)="-",_xlpm.rb,_xlpm.rc))))} -> 7 | CN7: =IF(B7="","",F7-0.5) -> 0.03125 | CO7: {=IF(B7="","",_xlfn.TEXTJOIN("",,MID(B7,_xlfn.SEQUENCE(LEN(B7),,LEN(B7),-1),1)))} -> 13 | CP7: {=IF(B7="","",BASE2DEC(CO7,16))} -> 19 | CQ7: =IF(B7="","",IF(AND(LEN(B7)<16,LEN(B7)=LEN(SUBSTITUTE(SUBSTITUTE(SUBSTITUTE(SUBSTITUTE(SUBSTITUTE(SUBSTITUTE(B7,"a",""),"b",""),"c",""),"d",""),"e",""),"f",""))),--B7,"")) -> 31 | CR7: {=IF(B7="","",IF(LEN(D7)<=15,BASE2DEC(D7,16),""))} -> 73 | CS7: {=IF(B7="","",_xlfn.LET(_xlpm.p,REPT("0",MOD(-LEN(B7),4))&B7,_xlfn.TEXTJOIN(" ",,MID(_xlpm.p,_xlfn.SEQUENCE(LEN(_xlpm.p)/4,,1,4),4))))} -> 0031 | CT7: {=IF(B7="","",UPPER(_xlfn.LET(_xlpm.p,REPT("0",64-LEN(B7))&B7,_xlfn.TEXTJOIN(" ",,MID(_xlpm.p,_xlfn.SEQUENCE(8,,1,8),8)))))} -> 00000000 00000000 00000000 00000000 00000000 00000000 00000000 00000031 | CU7: {=IF(B7="","",IF(LEN(D7)<=6,_xlfn.LET(_xlpm.n,VALUE(D7),_xlpm.ones,{"","one","two","three","four","five","six","seven","eight","nine","ten","eleven","twelve","thirteen","fourteen","fifteen","sixteen","seventeen","eighteen","nineteen"},_xlpm.tens,{"","","twenty","thirty","forty","fifty","sixty","seventy","eighty","ninety"},_xlpm.f,_xlfn.LAMBDA(_xlpm.x,TRIM(IF(_xlpm.x>=100,INDEX(_xlpm.ones,INT(_xlpm.x/100)+1)&" hundred ","")&IF(MOD(_xlpm.x,100)<20,INDEX(_xlpm.ones,MOD(_xlpm.x,100)+1),INDEX(_xlpm.tens,INT(MOD(_xlpm.x,100)/10)+1)&IF(MOD(_xlpm.x,10)>0,"-"&INDEX(_xlpm.ones,MOD(_xlpm.x,10)+1),"")))),TRIM(IF(_xlpm.n>=1000,_xlpm.f(INT(_xlpm.n/1000))&" thousand ","")&IF(MOD(_xlpm.n,1000)>0,_xlpm.f(MOD(_xlpm.n,1000)),""))),""))} -> forty-nine | CV7: no | CW7: 7 | CX7: 1 | CY7: 7 | CZ7: yes | DA7: no | DB7: 6 | DC7: 15 below 2^6 | DD7: 55 | DE7: 6 | DF7: 45 | DG7: 4 | DH7: odd | DI7: cMahea7zqjxrtgAbB7LSGbcQUr1uX1ojuat9jZodMN87iWuZkMNo | DJ7: n4EqjfTKnqTXz6AcJCB4wB8yKnGUinug6t | DK7: tb1qlylvxn57xj503lmavqxd4kpsg7cmedzukwzg2y | DL7: bc1plf7y7rs8y0z844yadzmtpg5rre439v4le07p99008edwnlt2tu4srzvtaw | DM7: fa7c4f0e0723c47ad49d68b6b0a2831e6b12b2bfcbfc1295ef3e5ae9fd6a5f2b | DN7: T33ydQRKp4FCW5LCLLUB7deioUMoveiwekdwUwyfRDeGyfMu7Wd2 | DO7: LhwqhpgB4UGLTnP9kmBzPGzQg133vnMf5y | DP7: ltc1qlylvxn57xj503lmavqxd4kpsg7cmedzuc5rlf8 | DQ7: QNcdLVw8fHkixm6NNyN6nVwxKek4u7qrioRbQmjxac5TuhsaBucn | DR7: DTryysJzHDvZjysbKDCFf26FLvQ5AdFGC8 | DS7: A/LayZHMTOS56kSIflx8C85YyAB0q51NuusoUxt3OfUw | DT7: {=IF(B7="","",_xlfn.TEXTJOIN("",,HEX2BIN(MID(BQ7,_xlfn.SEQUENCE(40),1),4)))} -> 0101000000010111100000110010001010110010000000110111100111011011010010101001010110001001010110001110111101001001100010001101101101101101100111101001111000100000
A8: 7 | B8: 4c | C8: 1001100 | D8: 76 | E8: 12 | F8: 0.1875 | G8: 3 | H8: 2 | I8: 1111101 | J8: 6 | K8: 1030 | L8: 114 | M8: 2c | N8: 0011001 | O8: 25 | P8: 1101010 | Q8: 1110011 | R8: 51 | S8: 4c00000000000000000000000000000000000000000000000000000000000000 | T8: 1.5510204 | U8: 0.42857143 | V8: KwDiBf89QgGbjEhKnhXJuH7LrciVrZi3qYjgd9M7rFU7hDgvu64y | W8: 5HpHagT65TZzG1PH3CSu63k8DbpvD8s5ip4nEB3kEsreKD614Nu | X8: AAAAAAAAAAAAAAAAAAAAAAAAAAAAAAAAAAAAAAAAAEw= | Y8: 1110001000011001001011101000101001111101110110001101110100011100100010000011001000011001010110011011010001110111100101101000101110010100000110101010100101110011 | Z8: 6 | AA8: 5 | AB8: 79 | AC8: 1.8898224 | AD8: 1.1338934 | AE8: 2 | AF8: 13 | AG8: 4 | AH8: 67 | AI8: 6.2479275 | AJ8: 3.5849625 | AK8: 0011001 | AL8: 0100110 | AM8: 0110011 | AN8: 2 | AO8: 2 | AP8: 4 | AQ8: 1x1,0x2,1x2,0x2 | AR8: 2 | AS8: 4 | AT8: 4:1 c:1 | AU8: 1 | AV8: 1 | AW8: 6 | AX8: 10 | AY8: 76 | AZ8: 76 | BA8: 27 | BB8: -22 | BC8: 77 | BD8: 75 | BE8: 0x00 00 00 00 00 00 00 00 00 00 00 00 00 00 00 00 00 00 00 00 00 00 00 00 00 00 00 00 00 00 00 4c | BF8: 0,0,0,0,0,0,0,0,0,0,0,0,0,0,0,0,0,0,0,0,0,0,0,0,0,0,0,0,0,0,0,76 | BG8: ...............................L | BH8: 0.0.0.76 | BI8: 25569.001 | BJ8: 24 | BK8: AAAAAAAAAAAAAAAAAAAAAAAAAAAAAAAAAAAAAAAAAAAAAAAAABGA==== | BL8: AAAAAAAAAAAAAAAAAAAAAAAAAAAAAAAAAAAAAAAAAEw | BM8: fffffffffffffffffffffffffffffffebaaedce6af48a03bbfd25e8cd03640f5 | BN8: 96516a8f65774275278d0d7420a88df0ac44bd64c7bae07c3fe397c5b3300b23 | BO8: bdacd9a05fb9fb73108c0a99d567fba9b2f75ab36207e1557f6bf255f1337ff0 | BP8: 0496516a8f65774275278d0d7420a88df0ac44bd64c7bae07c3fe397c5b3300b23bdacd9a05fb9fb73108c0a99d567fba9b2f75ab36207e1557f6bf255f1337ff0 | BQ8: 9362a33d628569a2edf58c037bed601c78556497 | BR8: 1ESJVfV5UVERkWgVNfMjsLwJT88yMJHi8R | BS8: 33NmypyeTdoE2tdj2tZwAQMCRranteifcy | BT8: bc1qugvjaznamrw3ezpjr9vmgauk3w2p42tn3txcnx | BU8: 6.5634881e-76 | BV8: 1001011001010001011010101000111101100101011101110100001001110101001001111000110100001101011101000010000010101000100011011111000010101100010001001011110101100100110001111011101011100000011111000011111111100011100101111100010110110011001100000000101100100011 | BW8: 6 | BX8: 3 | BY8: 1.8898224 | BZ8: -0.37796447 | CA8: =IF(B8="","",IF(A8<8,"",_xlfn.LET(_xlpm.n,A8,_xlpm.k,G8,_xlpm.R,AP8,_xlpm.mu,1+2*_xlpm.k*(_xlpm.n-_xlpm.k)/_xlpm.n,_xlpm.v,2*_xlpm.k*(_xlpm.n-_xlpm.k)*(2*_xlpm.k*(_xlpm.n-_xlpm.k)-_xlpm.n)/(_xlpm.n^2*(_xlpm.n-1)),IF(_xlpm.v<=0,"",(_xlpm.R-_xlpm.mu)/SQRT(_xlpm.v))))) | CB8: {=IF(B8="","",IF(A8<8,"",_xlfn.LET(_xlpm.b,--MID(C8,_xlfn.SEQUENCE(A8-1),1),_xlpm.c,--MID(C8,_xlfn.SEQUENCE(A8-1,,2),1),IFERROR(CORREL(_xlpm.b,_xlpm.c),""))))} | CC8: =IF(B8="","",LOG(A8,2)) -> 2.8073549 | CD8: =IF(B8="","",MAX(AN8,AO8)-CC8) -> -0.80735492 | CE8: {=IF(B8="","",IF(LEN(B8)<16,"",_xlfn.LET(_xlpm.d,MID("0123456789abcdef",_xlfn.SEQUENCE(16),1),_xlpm.c,LEN(B8)-LEN(SUBSTITUTE(B8,_xlpm.d,"")),_xlpm.ex,LEN(B8)/16,SUM((_xlpm.c-_xlpm.ex)^2/_xlpm.ex))))} | CF8: =IF(CE8="","",_xlfn.CHISQ.DIST.RT(CE8,15)) | CG8: {=IF(OR(B8="",B7=""),"",_xlfn.LET(_xlpm.a,C8,_xlpm.b,REPT("0",A8-LEN(C7))&C7,_xlpm.m,MID(_xlpm.a,_xlfn.SEQUENCE(A8),1)=MID(_xlpm.b,_xlfn.SEQUENCE(A8),1),IFERROR(MATCH(FALSE,_xlpm.m,0)-1,A8)))} -> 0 | CH8: {=IF(OR(B8="",B7=""),"",_xlfn.LET(_xlpm.a,C8,_xlpm.b,REPT("0",A8-LEN(C7))&C7,_xlpm.n,A8,_xlpm.m,MID(_xlpm.a,_xlfn.SEQUENCE(_xlpm.n,,_xlpm.n,-1),1)=MID(_xlpm.b,_xlfn.SEQUENCE(_xlpm.n,,_xlpm.n,-1),1),IFERROR(MATCH(FALSE,_xlpm.m,0)-1,_xlpm.n)))} -> 0 | CI8: =IF(OR(B8="",B7=""),"",F8-F7) -> -0.34375 | CJ8: =IF(OR(B8="",B7=""),"",IFERROR(FIND(B7,B8)>0,FALSE)) -> FALSE | CK8: =IF(OR(B8="",B7=""),"",IFERROR(FIND(C7,C8)>0,FALSE)) -> FALSE | CL8: =IF(OR(B8="",B7=""),"",IFERROR(FIND(C7,C8),"")) | CM8: {=IF(OR(B8="",B7=""),"",_xlfn.LET(_xlpm.pv,D7,_xlpm.ra,BIGSUB(D8,_xlpm.pv),_xlpm.rb,BIGSUB(_xlpm.ra,_xlpm.pv),_xlpm.rc,BIGSUB(_xlpm.rb,_xlpm.pv),IF(LEFT(_xlpm.rb,1)="-",_xlpm.ra,IF(LEFT(_xlpm.rc,1)="-",_xlpm.rb,_xlpm.rc))))} -> 27 | CN8: =IF(B8="","",F8-0.5) -> -0.3125 | CO8: {=IF(B8="","",_xlfn.TEXTJOIN("",,MID(B8,_xlfn.SEQUENCE(LEN(B8),,LEN(B8),-1),1)))} -> c4 | CP8: {=IF(B8="","",BASE2DEC(CO8,16))} -> 196 | CQ8: =IF(B8="","",IF(AND(LEN(B8)<16,LEN(B8)=LEN(SUBSTITUTE(SUBSTITUTE(SUBSTITUTE(SUBSTITUTE(SUBSTITUTE(SUBSTITUTE(B8,"a",""),"b",""),"c",""),"d",""),"e",""),"f",""))),--B8,"")) | CR8: {=IF(B8="","",IF(LEN(D8)<=15,BASE2DEC(D8,16),""))} -> 118 | CS8: {=IF(B8="","",_xlfn.LET(_xlpm.p,REPT("0",MOD(-LEN(B8),4))&B8,_xlfn.TEXTJOIN(" ",,MID(_xlpm.p,_xlfn.SEQUENCE(LEN(_xlpm.p)/4,,1,4),4))))} -> 004c | CT8: {=IF(B8="","",UPPER(_xlfn.LET(_xlpm.p,REPT("0",64-LEN(B8))&B8,_xlfn.TEXTJOIN(" ",,MID(_xlpm.p,_xlfn.SEQUENCE(8,,1,8),8)))))} -> 00000000 00000000 00000000 00000000 00000000 00000000 00000000 0000004C | CU8: {=IF(B8="","",IF(LEN(D8)<=6,_xlfn.LET(_xlpm.n,VALUE(D8),_xlpm.ones,{"","one","two","three","four","five","six","seven","eight","nine","ten","eleven","twelve","thirteen","fourteen","fifteen","sixteen","seventeen","eighteen","nineteen"},_xlpm.tens,{"","","twenty","thirty","forty","fifty","sixty","seventy","eighty","ninety"},_xlpm.f,_xlfn.LAMBDA(_xlpm.x,TRIM(IF(_xlpm.x>=100,INDEX(_xlpm.ones,INT(_xlpm.x/100)+1)&" hundred ","")&IF(MOD(_xlpm.x,100)<20,INDEX(_xlpm.ones,MOD(_xlpm.x,100)+1),INDEX(_xlpm.tens,INT(MOD(_xlpm.x,100)/10)+1)&IF(MOD(_xlpm.x,10)>0,"-"&INDEX(_xlpm.ones,MOD(_xlpm.x,10)+1),"")))),TRIM(IF(_xlpm.n>=1000,_xlpm.f(INT(_xlpm.n/1000))&" thousand ","")&IF(MOD(_xlpm.n,1000)>0,_xlpm.f(MOD(_xlpm.n,1000)),""))),""))} -> seventy-six | CV8: no | CW8: 2 | CX8: 2 | CY8: 2 × 19 | CZ8: no | DA8: no | DB8: 6 | DC8: 12 above 2^6 | DD8: 89 | DE8: 13 | DF8: 78 | DG8: 2 | DH8: even | DI8: cMahea7zqjxrtgAbB7LSGbcQUr1uX1ojuat9jZodMN87wxnxLPqt | DJ8: n28TB51LhDdNktZCsWetq3FNqCD3X8B2gF | DK8: tb1qugvjaznamrw3ezpjr9vmgauk3w2p42tnmdatg4 | DL8: bc1pp5mtkgk6rv7se4x92ladpe458kr8nd6q9c08xnyztkjekwmq96zsdhuy6y | DM8: 0d36bb22da1b3d0cd4c557fad0e6b43d8679b7402e1e734c825da59b3b602e85 | DN8: T33ydQRKp4FCW5LCLLUB7deioUMoveiwekdwUwyfRDeHD7GFm2Fn | DO8: LfqT9EEBxrSBEamkL5fpH96pBQycgDzwK2 | DP8: ltc1qugvjaznamrw3ezpjr9vmgauk3w2p42tn4huutk | DQ8: QNcdLVw8fHkixm6NNyN6nVwxKek4u7qrioRbQmjxac5U99bvf63v | DR8: DRkbRGs1Bc6QWnGBtXg5YtCerLLdsm1FAY | DS8: ApZRao9ld0J1J40NdCCojfCsRL1kx7rgfD/jl8WzMAsj | DT8: {=IF(B8="","",_xlfn.TEXTJOIN("",,HEX2BIN(MID(BQ8,_xlfn.SEQUENCE(40),1),4)))} -> 1001001101100010101000110011110101100010100001010110100110100010111011011111010110001100000000110111101111101101011000000001110001111000010101010110010010010111
